<?xml version="1.0"?>
<robot name="barista_robot">
     <material name="red">
      <color rgba="1.0 0.0 0.0 1"/>
  </material>

  <material name="green_light">
      <color rgba="0.0 1.0 0.0 1"/>
  </material>

  <material name="green_dark">
    <color rgba="0.0 0.5 0.0 1"/>
  </material>

  <material name="blue">
      <color rgba="0.0 0.0 1.0 1"/>
  </material>

  <material name="yellow">
      <color rgba="1.0 1.0 0.0 1"/>
  </material>

  <material name="black">
      <color rgba="0.0 0.0 0.0 1"/>
  </material>

  <material name="white">
      <color rgba="1.0 1.0 1.0 1"/>
  </material>     

  <link name="base_link">
    <visual>        
      <geometry>
      <cylinder radius="0.178" length="0.155"/>
      </geometry>
    </visual>

    <collision>
          <geometry>
      <cylinder radius="0.178" length="0.155"/>
      </geometry>
    </collision>

        <inertial>
      <mass value="17.8"/>
      <origin rpy="0 0 0" xyz="0 0 0"/>
      <inertia ixx="0.17663088333333335" ixy="0" ixz="0" iyy="0.17663088333333335" iyz="0" izz="0.2819876"/>
    </inertial>

  </link>


  <joint name="base_link_to_rod_1" type="fixed">
        <origin rpy="0 0 1.5708" xyz="0.0356 0.140 0.0775" />
        <parent link="base_link" />
        <child link="base_to_head_rod_1" />/>
   </joint>
  <link name="base_to_head_rod_1">
      <visual>
    <origin rpy="0 0 1.5707" xyz="0 0 0.110" /> 
      <geometry>
        <cylinder radius="0.010" length="0.220"/>
      </geometry>
    </visual>
    
    <collision>
    <origin rpy="0 0 1.5707" xyz="0 0 0.110" /> 
      <geometry>
        <cylinder radius="0.010" length="0.220"/>
      </geometry>
    </collision>
    
      <inertial>
      <mass value="0.1"/>
    <origin rpy="0 0 1.5707" xyz="0 0 0.110" /> 
      <inertia ixx="0.00040583333333333335" ixy="0" ixz="0" iyy="0.00040583333333333335" iyz="0" izz="0.000005"/>
    </inertial>
  </link>


  <joint name="base_link_to_rod_2" type="fixed">
        <origin rpy="0 0 1.5708" xyz="-0.0356 0.140 0.0775" />
        <parent link="base_link" />
        <child link="base_to_head_rod_2" />/>
   </joint>
  <link name="base_to_head_rod_2">
      <visual>
    <origin rpy="0 0 1.5707" xyz="0 0 0.110" /> 
      <geometry>
        <cylinder radius="0.010" length="0.220"/>
      </geometry>
    </visual>
    <collision>
        <origin rpy="0 0 1.5707" xyz="0 0 0.110" /> 
      <geometry>
        <cylinder radius="0.010" length="0.220"/>
      </geometry>
    </collision>
          <inertial>
      <mass value="0.1"/>
    <origin rpy="0 0 1.5707" xyz="0 0 0.110" /> 
      <inertia ixx="0.00040583333333333335" ixy="0" ixz="0" iyy="0.00040583333333333335" iyz="0" izz="0.000005"/>
    </inertial>
  </link>


  <joint name="base_link_to_rod_3" type="fixed">
        <origin rpy="0 0 1.5708" xyz="0.0356 -0.140 0.0775" />
        <parent link="base_link" />
        <child link="base_to_head_rod_3" />/>
   </joint>
  <link name="base_to_head_rod_3">
      <visual>
    <origin rpy="0 0 1.5707" xyz="0 0 0.110" /> 
      <geometry>
        <cylinder radius="0.010" length="0.220"/>
      </geometry>
    </visual>
    <collision>
        <origin rpy="0 0 1.5707" xyz="0 0 0.110" /> 
      <geometry>
        <cylinder radius="0.010" length="0.220"/>
      </geometry>
    </collision>
          <inertial>
      <mass value="0.1"/>
    <origin rpy="0 0 1.5707" xyz="0 0 0.110" /> 
      <inertia ixx="0.00040583333333333335" ixy="0" ixz="0" iyy="0.00040583333333333335" iyz="0" izz="0.000005"/>
    </inertial>
  </link>



  <joint name="base_link_to_rod_4" type="fixed">
        <origin rpy="0 0 1.5708" xyz=" -0.0356 -0.140 0.0775" />
        <parent link="base_link" />
        <child link="base_to_head_rod_4" />/>
   </joint>
  <link name="base_to_head_rod_4">
      <visual>
    <origin rpy="0 0 1.5707" xyz="0 0 0.110" />
      <geometry>
        <cylinder radius="0.010" length="0.220"/>
      </geometry>
    </visual>
    <collision>
        <origin rpy="0 0 1.5707" xyz="0 0 0.110" />
      <geometry>
        <cylinder radius="0.010" length="0.220"/>
      </geometry>
    </collision>
          <inertial>
      <mass value="0.1"/>
    <origin rpy="0 0 1.5707" xyz="0 0 0.110" />
      <inertia ixx="0.00040583333333333335" ixy="0" ixz="0" iyy="0.00040583333333333335" iyz="0" izz="0.000005"/>
    </inertial>
  </link>


  <joint name="base_link_to_head_link" type="fixed">
        <origin rpy="0 0 0" xyz="0 0 0.2975" />
        <parent link="base_link" />
        <child link="head_link" />/>
   </joint>
  <link name="head_link">
      <visual>
    <origin rpy="0 0 0" xyz="0 0 0.045" /> 
      <geometry>
        <cylinder radius="0.178" length="0.090"/>
      </geometry>
    </visual>
   <collision>
       <origin rpy="0 0 0" xyz="0 0 0.045" /> 
      <geometry>
        <cylinder radius="0.178" length="0.090"/>
      </geometry>
   </collision>
      <inertial>
      <mass value="10.335"/>
    <origin rpy="0 0 0" xyz="0 0 0.045" /> 
      <inertia ixx="0.08883966" ixy="0" ixz="0" iyy="0.08883966" iyz="0" izz="0.16372707"/>
    </inertial>

  </link>


  <joint name="joint_left_wheel" type="continuous">
    <origin rpy="0 0 0" xyz="0 0.14 -0.075"/>
    <child link="left_wheel"/>
    <parent link="base_link"/>
    <axis rpy="0 0 0" xyz="0 1 0"/>
    <limit effort="10000" velocity="1000"/>
    <joint_properties damping="1.0" friction="1.0"/>
  </joint>
  <link name="left_wheel">      
      <visual>
        <origin rpy="1.5707 0 0" xyz="0 0 0"/>
        <geometry>
          <cylinder length="0.0206" radius="0.0352"/>
        </geometry>
      </visual>
      <collision>
              <origin rpy="1.5707 0 0" xyz="0 0 0"/>
        <geometry>
          <cylinder length="0.0206" radius="0.0352"/>
        </geometry>
      </collision>
            <inertial>
      <mass value="1.0"/>
        <origin rpy="1.5707 0 0" xyz="0 0 0"/>
      <inertia ixx="0.00034512333333333334" ixy="0" ixz="0" iyy="0.00034512333333333334" iyz="0" izz="0.00061952"/>
    </inertial>
  </link>


  <joint name="joint_right_wheel" type="continuous">
    <origin rpy="0 0 0" xyz="0 -0.14 -0.075"/>
    <child link="right_wheel"/>
    <parent link="base_link"/>
    <axis rpy="0 0 0" xyz="0 1 0"/>
    <limit effort="10000" velocity="1000"/>
    <joint_properties damping="1.0" friction="1.0"/>
  </joint>
  <link name="right_wheel">      
      <visual>
        <origin rpy="1.5707 0 0" xyz="0 0 0"/>
        <geometry>
          <cylinder length="0.0206" radius="0.0352"/>
        </geometry>
      </visual>
      <collision>
              <origin rpy="1.5707 0 0" xyz="0 0 0"/>
        <geometry>
          <cylinder length="0.0206" radius="0.0352"/>
        </geometry>
        </collision>
                  <inertial>
      <mass value="1.0"/>
        <origin rpy="1.5707 0 0" xyz="0 0 0"/>
      <inertia ixx="0.00034512333333333334" ixy="0" ixz="0" iyy="0.00034512333333333334" iyz="0" izz="0.00061952"/>
    </inertial>
  </link>



  <joint name="front_yaw_joint" type="continuous">
    <origin rpy="0 0 0" xyz="0.14 0 -0.075" />
    <parent link="base_link" />
    <child link="front_yaw_link" />
    <axis xyz="0 0 1" />
    <limit effort="1000.0" velocity="100.0" />
    <dynamics damping="0.0" friction="0.1"/>
  </joint>
  <link name="front_yaw_link">
    <visual>
        <origin rpy="0 1.5707 1.5707" xyz="0 0 0"/>
        <geometry>
          <cylinder length="0.0206" radius="0.0352"/>
        </geometry>
        <material name="blue"/>
      </visual>
      <collision>
              <origin rpy="0 1.5707 1.5707" xyz="0 0 0"/>
        <geometry>
          <cylinder length="0.0206" radius="0.0352"/>
        </geometry>
      </collision>
  </link>




  <joint name="front_roll_joint" type="continuous">
    <origin rpy="0 0 0" xyz="0 0 0" />
    <parent link="front_yaw_link" />
    <child link="front_roll_link" />
    <axis xyz="1 0 0" />
    <limit effort="1000.0" velocity="100.0" />
    <dynamics damping="0.0" friction="0.1"/>
  </joint>
  <link name="front_roll_link">
      <visual>
        <origin rpy="0 1.5707 1.5707" xyz="0 0 0"/>
        <geometry>
          <cylinder length="0.0206" radius="0.0352"/>
        </geometry>
        <material name="red"/>
      </visual>
      <collision>
              <origin rpy="0 1.5707 1.5707" xyz="0 0 0"/>
        <geometry>
          <cylinder length="0.0206" radius="0.0352"/>
        </geometry>
      </collision>
  </link>
    <gazebo reference="front_roll_link">
        <material>Gazebo/Red</material>
    </gazebo>



  <joint name="front_pitch_joint" type="continuous">
    <origin rpy="0 0 0" xyz="0 0 0" />
    <parent link="front_roll_link" />
    <child link="front_pitch_link" />
    <axis xyz="0 1 0" />
    <limit effort="1000.0" velocity="100.0" />
    <dynamics damping="0.0" friction="0.1"/>
  </joint>
  <link name="front_pitch_link">
    <visual>
      <origin rpy="0 1.5707 1.5707" xyz="0 0 0"/>
      <geometry>
        <sphere radius="0.0352"/>
      </geometry>
      <material name="green_dark"/>
    </visual>
    <collision>
          <origin rpy="0 1.5707 1.5707" xyz="0 0 0"/>
      <geometry>
        <sphere radius="0.0352"/>
      </geometry>
    </collision>
  </link>




<!-- Caster Wheel Back -->
  <joint name="back_yaw_joint" type="continuous">
    <origin rpy="0 0 0" xyz="-0.14 0 -0.075" />
    <parent link="base_link" />
    <child link="back_yaw_link" />
    <axis xyz="0 0 1" />
    <limit effort="1000.0" velocity="100.0" />
    <dynamics damping="0.0" friction="0.1"/>
  </joint>
  <link name="back_yaw_link">
    <visual>
        <origin rpy="0 1.5707 1.5707" xyz="0 0 0"/>
        <geometry>
          <cylinder length="0.0206" radius="0.0352"/>
        </geometry>
        <material name="blue"/>
      </visual>
      <collision>
              <origin rpy="0 1.5707 1.5707" xyz="0 0 0"/>
        <geometry>
          <cylinder length="0.0206" radius="0.0352"/>
        </geometry>
      </collision>

  </link>




  <joint name="back_roll_joint" type="continuous">
    <origin rpy="0 0 0" xyz="0 0 0" />
    <parent link="back_yaw_link" />
    <child link="back_roll_link" />
    <axis xyz="1 0 0" />
    <limit effort="1000.0" velocity="100.0" />
    <dynamics damping="0.0" friction="0.1"/>
  </joint>

  <link name="back_roll_link">
      <visual>
        <origin rpy="0 1.5707 1.5707" xyz="0 0 0"/>
        <geometry>
          <cylinder length="0.0206" radius="0.0352"/>
        </geometry>
        <material name="red"/>
      </visual>
      <collision>
              <origin rpy="0 1.5707 1.5707" xyz="0 0 0"/>
        <geometry>
          <cylinder length="0.0206" radius="0.0352"/>
        </geometry>
      </collision>
  </link>



  <joint name="back_pitch_joint" type="continuous">
    <origin rpy="0 0 0" xyz="0 0 0" />
    <parent link="back_roll_link" />
    <child link="back_pitch_link" />
    <axis xyz="0 1 0" />
    <limit effort="1000.0" velocity="100.0" />
    <dynamics damping="0.0" friction="0.1"/>
  </joint>

  <link name="back_pitch_link">
    <visual>
      <origin rpy="0 1.5707 1.5707" xyz="0 0 0"/>
      <geometry>
        <sphere radius="0.0352"/>
      </geometry>
      <material name="green_dark"/>
    </visual>
    <collision>
          <origin rpy="0 1.5707 1.5707" xyz="0 0 0"/>
      <geometry>
        <sphere radius="0.0352"/>
      </geometry>
    </collision>
  </link>



</robot>

